Workbook

Sheet Setup-Sheet
B2: *this sheet is for recap only, no data in this sheet should be used for formulas
B4: Setup name | C4: Soft
C6: Front | D6: Rear | E6: Ratio
B7: Spring | C7: 190 | D7: 210 | F7: N/mm
B8: Ground rate | C8: 88 | D8: 106 | E8: =C8/(C8+D8) -> 0.45360825 | F8: N/mm
B9: 1-dof ride frequency | C9: 2.9 | D9: 3.1 | E9: =C9/(C9+D9) -> 0.48333333 | F9: Hz
B10: 2-dof ride frequency | C10: 2.58 | D10: 2.69 | E10: =C10/(C10+D10) -> 0.48956357 | F10: Hz
B11: Anti-Roll Bar | C11: 1200 | D11: 100 | F11: Nm/deg
B12: 1-dof elastic roll stiffness | C12: 3401 | D12: 2579 | E12: =C12/(C12+D12) -> 0.5687291 | F12: Nm/deg
B14: Setup name | C14: Stiff
C16: Front | D16: Rear | E16: Ratio
B17: Spring | C17: 230 | D17: 270 | F17: N/mm
B18: Ground rate | C18: 106 | D18: 125 | E18: =C18/(C18+D18) -> 0.45887446 | F18: N/mm
B19: 1-dof ride frequency | C19: 3.2 | D19: 3.4 | E19: =C19/(C19+D19) -> 0.48484848 | F19: Hz
B20: 2-dof ride frequency | C20: 2.77 | D20: 2.85 | E20: =C20/(C20+D20) -> 0.49288256 | F20: Hz
B21: Anti-Roll Bar | C21: 1700 | D21: 100 | F21: Nm/deg
B22: 1-dof elastic roll stiffness | C22: 3864 | D22: 3010 | E22: =C22/(C22+D22) -> 0.56211813 | F22: Nm/deg

Sheet front motion ratio
B2: SCG004C | F2: P4/5 Competizione m | J2: Color code
B3: Massa Veicolo | C3: 2250 | D3: [kg] | F3: Massa Veicolo | G3: 1400 | H3: [kg] | J3: Formula result
B4: Ripartizione massa ant | C4: 0.5 | F4: Ripartizione massa ant | G4: 0.46 | J4: Input data
B5: Ripartizione massa post | C5: 0.5 | F5: Ripartizione massa post | G5: 0.54 | J5: Constrained input data
B6: Massa passeggeri | C6: 0 | D6: [kg] | F6: Massa passeggeri | G6: 0 | H6: [kg] | J6: Result = OK
B7: Massa carburante | C7: 0 | D7: [kg] | F7: Massa carburante | G7: 0 | H7: [kg] | J7: Result = KO
B9: Massa totale | C9: =C3+C6+C7 -> 2250 | D9: [kg] | F9: Massa totale | G9: =G3+G6+G7 -> 1400 | H9: [kg] | J9: Static damper ratio
B10: Massa assale ant | C10: =C9*C4 -> 1125 | D10: [kg] | F10: Massa assale ant | G10: =G9*G4 -> 644 | H10: [kg] | J10: Race | K10: 1 | L10: =C15 -> 1
B11: Massa assale post | C11: =C9*C5 -> 1125 | D11: [kg] | F11: Massa assale post | G11: =G9*G5 -> 756 | H11: [kg] | J11: Street | K11: 2 | L11: =+L10 -> 1
B12: Massa non sospesa assale ant | C12: 140 | D12: [kg] | E12: guess | F12: Massa non sospesa assale ant | G12: 60 | H12: [kg] | J12: Lift | K12: 3 | L12: =+L10 -> 1
B13: Massa non sospesa assale post | C13: 140 | D13: [kg] | E13: guess | F13: Massa non sospesa assale post | G13: 60 | H13: [kg]
J14: KW advised spring rates
B15: Motion ratio (Standard) | C15: 1 | F15: Damper ratio (Highway) | G15: 1.45 | J15: Front | K15: 140 | L15: [N/mm]
B16: Frequenza moti di cassa (Standard) | C16: 1.7 | D16: [Hz] | F16: Frequenza moti di cassa | G16: 2.6 | H16: [Hz] | J16: Rear | K16: 150 | L16: [N/mm]
B17: Rigidezza verticale pneumatico | C17: 250 | D17: [N/mm] | F17: Rigidezza verticale pneumatico | G17: 278 | H17: [N/mm]
B19: Rigidezza molla anteriore (1 g.d.l.) | C19: =2*(PI()*C16*C15)^2*(C10-C12)/1000 -> 56.190619 | D19: [N/mm] | F19: Rigidezza molla anteriore (1 g.d.l.) | G19: =2*(PI()*G16*G15)^2*G10/1000 -> 180.6751 | H19: [N/mm]
B20: Rigidezza molla anteriore (2 g.d.l.) | C20: =(2*(PI()*C16*C15)^2*(C10-C12)*C17*1000/(C17*1000-2*PI()^2*C16^2*(C10-C12)))/1000 -> 72.48181 | D20: [N/mm] | F20: Rigidezza molla anteriore (2 g.d.l.) | G20: =(2*(PI()*G16*G15)^2*(G10-G12)*G17*1000/(G17*1000-2*PI()^2*G16^2*(G10-G12)))/1000 -> 227.65758 | H20: [N/mm]
B22: Rigidezza molla anteriore (2 g.d.l.) | C22: 70 | D22: [N/mm] | F22: Rigidezza molla anteriore (2 g.d.l.) | G22: 310 | H22: [N/mm]
B23: Frequenza massa non sospesa ant. | C23: =1/(2*PI())*SQRT(1000*(C22/C15^2+C17)/(C12*0.5)) -> 10.760838 | D23: [Hz] | F23: Frequenza massa non sospesa ant. | G23: =1/(2*PI())*SQRT(1000*(G22/G15^2+G17)/(G12*0.5)) -> 18.953109 | H23: [Hz]
B24: Rigidezza a terra ant. (2g.d.l.) | C24: =((C22/C15^2)^-1+C17^-1)^-1 -> 54.6875 | D24: [N/mm] | F24: Rigidezza a terra (2 g.d.l.) Corner | G24: =((G22/G15^2)^-1+G17^-1)^-1 -> 96.344865 | H24: [N/mm]
B25: Rigidezza a terra (1 g.d.l.) | C25: =C22/C15^2 -> 70 | D25: [N/mm] | F25: Rigidezza a terra (1 g.d.l.) | G25: =G22/G15^2 -> 147.44352 | H25: [N/mm]
E26: 1.6
B27: Setup name | C27: Soft
B28: Spring | C28: 190 | D28: N/mm
B29: Ground rate | C29: 88 | D29: N/mm
B30: 1-dof ride frequency | C30: 2.9 | D30: Hz
B31: 2-dof ride frequency | C31: 2.58 | D31: Hz
B33: Modded to subtract unsprung mass

Sheet front wheel travel
G2: Ride height | M2: Color code
B3: Max wheel center travel | C3: =+C4+C5 -> 90 | D3: [mm] | E3: Unused travel [mm] | H3: Delta height | I3: d-race | M3: Formula result
B4: Rebound travel | C4: 30 | D4: [mm] | E4: 0 | G4: Race | H4: 0 | I4: 0 | K4: [mm] | M4: Input data
B5: Bump travel | C5: 60 | D5: [mm] | E5: 0 | G5: Street | H5: 0 | I5: =I4+H5 -> 0 | K5: [mm] | M5: Constrained input data
G6: Lift | H6: 0 | I6: =I5+H6 -> 0 | K6: [mm] | M6: Result = OK
B7: D_tyre_road | C7: =21*25.4+245*0.35*2 -> 704.9 | D7: [mm] | M7: Result = KO
B8: D_tyre_race | C8: 640 | D8: [mm] | G8: Susp. Point vertical translation | H8: =0+H9 -> 0 | I8: [mm]
B9: delta_tyre_radius | C9: =(C7-C8)/2 -> 32.45 | D9: [mm] | G9: Wheel center pre-bump in std. static condition | H9: 0 | I9: [mm]
C12: Wheel center travel | H12: Spring travel
C13: Travel | D13: Bump | E13: Rebound | H13: Travel | I13: Bump | J13: Rebound
A14: 1 | B14: Race | C14: =C15 -> 90 | D14: =C14-E14 -> 60 | E14: =E15+H5 -> 30 | G14: Highway | H14: =C14/'front motion ratio'!$C$15 -> 90 | I14: =D14/'front motion ratio'!$C$15 -> 60 | J14: =E14/'front motion ratio'!$C$15 -> 30
A15: 2 | B15: Street | C15: =D15+E15 -> 90 | D15: =C5-E5-H9 -> 60 | E15: =E16 -> 30 | G15: Standard | H15: =C15/'front motion ratio'!$C$15 -> 90 | I15: =D15/'front motion ratio'!$C$15 -> 60 | J15: =E15/'front motion ratio'!$C$15 -> 30
A16: 3 | B16: Lift | C16: =D16+E16 -> 90 | D16: =C3-E4-E5-E16 -> 60 | E16: =C4-E4+H9-H6 -> 30 | G16: Offroad | H16: =C16/'front motion ratio'!$C$15 -> 90 | I16: =D16/'front motion ratio'!$C$15 -> 60 | J16: =E16/'front motion ratio'!$C$15 -> 30

Sheet front spring
A2: Front axle mass | B2: ='front motion ratio'!C10 -> 1125 | C2: [kg] | G2: Wheel center travel | L2: Spring travel | Q2: Color code
A3: Damper ratio | B3: ='front motion ratio'!C15 -> 1 | G3: Travel | H3: Bump | I3: Rebound | L3: Travel | M3: Bump | N3: Rebound | Q3: Formula result
E4: 1 | F4: =VLOOKUP($E$4,'front wheel travel'!$A$14:$E$16,2) -> Race | G4: =VLOOKUP($E$4,'front wheel travel'!$A$14:$E$16,3) -> 90 | H4: =G4-I4 -> 60 | I4: =VLOOKUP($E$4,'front wheel travel'!$A$14:$E$16,5) -> 30 | K4: =F4 -> Race | L4: =I8-H8 -> 110.1 | M4: =G8-H8 -> 75.692 | N4: =I8-G8 -> 34.408 | Q4: Input data
Q5: Constrained input data
G6: Damper length [mm] from CAD | Q6: Result = OK
G7: Static | H7: Bump (60) | I7: Rebound (-30) | J7: Rebound (-60) | Q7: Result = KO
G8: 449.592 | H8: 373.9 | I8: 484 | J8: 517.5 | Q8: From multibody
B10: Index | C10: Part-No. | D10: Free length [mm] | E10: Wire diameter [mm] | F10: Max spring travel Sn [mm] | G10: Spring rate [N/mm] | H10: Spring static travel [mm] | I10: Bump travel | J10: Spring left travel after max bump | K10: OK/KO | L10: Static spring length | M10: Rebound travel | O10: Rigidezza a terra corrispettiva 1 g.d.l. [N/mm] | P10: G su molla @ max bump
A11: Inner diameter 51mm | B11: 1 | C11: 60110178 | D11: 210 | E11: 8.25 | F11: 128 | G11: 30 | H11: =$B$2/2*9.81*$B$3/G11 -> 183.9375 | I11: =F11-H11 -> -55.9375 | J11: =I11-$M$4 -> -131.6295 | K11: =IF(J11<=0,"KO","OK") -> KO | L11: =D11-H11 -> 26.0625 | M11: =D11-L11 -> 183.9375 | O11: =G11/$B$3^2 -> 30 | P11: =G11*I11/$B$3/($B$2*9.81*0.5) -> -0.30411145
B12: 2 | C12: 60110132 | D12: 170 | E12: 8.25 | F12: 103 | G12: 40 | H12: =$B$2/2*9.81*$B$3/G12 -> 137.95312 | I12: =F12-H12 -> -34.953125 | J12: =I12-$M$4 -> -110.64513 | K12: =IF(J12<=0,"KO","OK") -> KO | L12: =D12-H12 -> 32.046875 | M12: =D12-L12 -> 137.95312 | O12: =G12/$B$3^2 -> 40 | P12: =G12*I12/$B$3/($B$2*9.81*0.5) -> -0.25336958
B13: 3 | C13: 60110133 | D13: 190 | E13: 8.75 | F13: 108 | G13: 40 | H13: =$B$2/2*9.81*$B$3/G13 -> 137.95312 | I13: =F13-H13 -> -29.953125 | J13: =I13-$M$4 -> -105.64513 | K13: =IF(J13<=0,"KO","OK") -> KO | L13: =D13-H13 -> 52.046875 | M13: =D13-L13 -> 137.95312 | O13: =G13/$B$3^2 -> 40 | P13: =G13*I13/$B$3/($B$2*9.81*0.5) -> -0.21712538
B14: 4 | C14: 60110134 | D14: 230 | E14: 9.25 | F14: 127 | G14: 40 | H14: =$B$2/2*9.81*$B$3/G14 -> 137.95312 | I14: =F14-H14 -> -10.953125 | J14: =I14-$M$4 -> -86.645125 | K14: =IF(J14<=0,"KO","OK") -> KO | L14: =D14-H14 -> 92.046875 | M14: =D14-L14 -> 137.95312 | O14: =G14/$B$3^2 -> 40 | P14: =G14*I14/$B$3/($B$2*9.81*0.5) -> -0.07939744
B15: 5 | C15: 60110147 | D15: 290 | E15: 9.75 | F15: 162 | G15: 40 | H15: =$B$2/2*9.81*$B$3/G15 -> 137.95312 | I15: =F15-H15 -> 24.046875 | J15: =I15-$M$4 -> -51.645125 | K15: =IF(J15<=0,"KO","OK") -> KO | L15: =D15-H15 -> 152.04688 | M15: =D15-L15 -> 137.95312 | O15: =G15/$B$3^2 -> 40 | P15: =G15*I15/$B$3/($B$2*9.81*0.5) -> 0.17431193
B16: 6 | C16: 60110135 | D16: 310 | E16: 10 | F16: 165 | G16: 40 | H16: =$B$2/2*9.81*$B$3/G16 -> 137.95312 | I16: =F16-H16 -> 27.046875 | J16: =I16-$M$4 -> -48.645125 | K16: =IF(J16<=0,"KO","OK") -> KO | L16: =D16-H16 -> 172.04688 | M16: =D16-L16 -> 137.95312 | O16: =G16/$B$3^2 -> 40 | P16: =G16*I16/$B$3/($B$2*9.81*0.5) -> 0.19605844
B17: 7 | C17: 60110111 | D17: 140 | E17: 8.5 | F17: 81 | G17: 50 | H17: =$B$2/2*9.81*$B$3/G17 -> 110.3625 | I17: =F17-H17 -> -29.3625 | J17: =I17-$M$4 -> -105.0545 | K17: =IF(J17<=0,"KO","OK") -> KO | L17: =D17-H17 -> 29.6375 | M17: =D17-L17 -> 110.3625 | O17: =G17/$B$3^2 -> 50 | P17: =G17*I17/$B$3/($B$2*9.81*0.5) -> -0.26605505
B18: 8 | C18: 60110131 | D18: 170 | E18: 9 | F18: 92 | G18: 50 | H18: =$B$2/2*9.81*$B$3/G18 -> 110.3625 | I18: =F18-H18 -> -18.3625 | J18: =I18-$M$4 -> -94.0545 | K18: =IF(J18<=0,"KO","OK") -> KO | L18: =D18-H18 -> 59.6375 | M18: =D18-L18 -> 110.3625 | O18: =G18/$B$3^2 -> 50 | P18: =G18*I18/$B$3/($B$2*9.81*0.5) -> -0.16638351
B19: 9 | C19: 60110136 | D19: 190 | E19: 9.25 | F19: 105 | G19: 50 | H19: =$B$2/2*9.81*$B$3/G19 -> 110.3625 | I19: =F19-H19 -> -5.3625 | J19: =I19-$M$4 -> -81.0545 | K19: =IF(J19<=0,"KO","OK") -> KO | L19: =D19-H19 -> 79.6375 | M19: =D19-L19 -> 110.3625 | O19: =G19/$B$3^2 -> 50 | P19: =G19*I19/$B$3/($B$2*9.81*0.5) -> -0.048589874
B20: 10 | C20: 60110175 | D20: 210 | E20: 9.5 | F20: 118 | G20: 50 | H20: =$B$2/2*9.81*$B$3/G20 -> 110.3625 | I20: =F20-H20 -> 7.6375 | J20: =I20-$M$4 -> -68.0545 | K20: =IF(J20<=0,"KO","OK") -> KO | L20: =D20-H20 -> 99.6375 | M20: =D20-L20 -> 110.3625 | O20: =G20/$B$3^2 -> 50 | P20: =G20*I20/$B$3/($B$2*9.81*0.5) -> 0.06920376
B21: 11 | C21: 60110137 | D21: 230 | E21: 9.75 | F21: 125 | G21: 50 | H21: =$B$2/2*9.81*$B$3/G21 -> 110.3625 | I21: =F21-H21 -> 14.6375 | J21: =I21-$M$4 -> -61.0545 | K21: =IF(J21<=0,"KO","OK") -> KO | L21: =D21-H21 -> 119.6375 | M21: =D21-L21 -> 110.3625 | O21: =G21/$B$3^2 -> 50 | P21: =G21*I21/$B$3/($B$2*9.81*0.5) -> 0.1326311
B22: 12 | C22: 60110148 | D22: 290 | E22: 10.5 | F22: 150 | G22: 50 | H22: =$B$2/2*9.81*$B$3/G22 -> 110.3625 | I22: =F22-H22 -> 39.6375 | J22: =I22-$M$4 -> -36.0545 | K22: =IF(J22<=0,"KO","OK") -> KO | L22: =D22-H22 -> 179.6375 | M22: =D22-L22 -> 110.3625 | O22: =G22/$B$3^2 -> 50 | P22: =G22*I22/$B$3/($B$2*9.81*0.5) -> 0.35915732
B23: 13 | C23: 60110138 | D23: 310 | E23: 10.75 | F23: 155 | G23: 50 | H23: =$B$2/2*9.81*$B$3/G23 -> 110.3625 | I23: =F23-H23 -> 44.6375 | J23: =I23-$M$4 -> -31.0545 | K23: =IF(J23<=0,"KO","OK") -> KO | L23: =D23-H23 -> 199.6375 | M23: =D23-L23 -> 110.3625 | O23: =G23/$B$3^2 -> 50 | P23: =G23*I23/$B$3/($B$2*9.81*0.5) -> 0.40446257
... B53: 43 | C53: 60110165 | D53: 130 | E53: 14 | F53: 49 | G53: 350 | H53: =$B$2/2*9.81*$B$3/G53 -> 15.766071 | I53: =F53-H53 -> 33.233929 | J53: =I53-$M$4 -> -42.458071 | K53: =IF(J53<=0,"KO","OK") -> KO | L53: =D53-H53 -> 114.23393 | M53: =D53-L53 -> 15.766071 | O53: =G53/$B$3^2 -> 350 | P53: =G53*I53/$B$3/($B$2*9.81*0.5) -> 2.1079397
A54: Inner diameter 61mm | B54: 44 | C54: 60110053 | D54: 250 | E54: 8.75 | F54: 165 | G54: 25 | H54: =$B$2/2*9.81*$B$3/G54 -> 220.725 | I54: =F54-H54 -> -55.725 | J54: =I54-$M$4 -> -131.417 | K54: =IF(J54<=0,"KO","OK") -> KO | L54: =D54-H54 -> 29.275 | M54: =D54-L54 -> 220.725 | O54: =G54/$B$3^2 -> 25 | P54: =G54*I54/$B$3/($B$2*9.81*0.5) -> -0.25246347
B55: 45 | C55: 60110105 | D55: 170 | E55: 8.25 | F55: 110 | G55: 30 | H55: =$B$2/2*9.81*$B$3/G55 -> 183.9375 | I55: =F55-H55 -> -73.9375 | J55: =I55-$M$4 -> -149.6295 | K55: =IF(J55<=0,"KO","OK") -> KO | L55: =D55-H55 -> -13.9375 | M55: =D55-L55 -> 183.9375 | O55: =G55/$B$3^2 -> 30 | P55: =G55*I55/$B$3/($B$2*9.81*0.5) -> -0.40197078
B56: 46 | C56: 60110009 | D56: 200 | E56: 9.25 | F56: 113 | G56: 30 | H56: =$B$2/2*9.81*$B$3/G56 -> 183.9375 | I56: =F56-H56 -> -70.9375 | J56: =I56-$M$4 -> -146.6295 | K56: =IF(J56<=0,"KO","OK") -> KO | L56: =D56-H56 -> 16.0625 | M56: =D56-L56 -> 183.9375 | O56: =G56/$B$3^2 -> 30 | P56: =G56*I56/$B$3/($B$2*9.81*0.5) -> -0.38566089
B57: 47 | C57: 60110051 | D57: 200 | E57: 8.75 | F57: 128 | G57: 30 | H57: =$B$2/2*9.81*$B$3/G57 -> 183.9375 | I57: =F57-H57 -> -55.9375 | J57: =I57-$M$4 -> -131.6295 | K57: =IF(J57<=0,"KO","OK") -> KO | L57: =D57-H57 -> 16.0625 | M57: =D57-L57 -> 183.9375 | O57: =G57/$B$3^2 -> 30 | P57: =G57*I57/$B$3/($B$2*9.81*0.5) -> -0.30411145
B58: 48 | C58: 60110010 | D58: 250 | E58: 9.25 | F58: 160 | G58: 30 | H58: =$B$2/2*9.81*$B$3/G58 -> 183.9375 | I58: =F58-H58 -> -23.9375 | J58: =I58-$M$4 -> -99.6295 | K58: =IF(J58<=0,"KO","OK") -> KO | L58: =D58-H58 -> 66.0625 | M58: =D58-L58 -> 183.9375 | O58: =G58/$B$3^2 -> 30 | P58: =G58*I58/$B$3/($B$2*9.81*0.5) -> -0.13013931
B59: 49 | C59: 60110055 | D59: 250 | E59: 9.75 | F59: 153 | G59: 35 | H59: =$B$2/2*9.81*$B$3/G59 -> 157.66071 | I59: =F59-H59 -> -4.6607143 | J59: =I59-$M$4 -> -80.352714 | K59: =IF(J59<=0,"KO","OK") -> KO | L59: =D59-H59 -> 92.339286 | M59: =D59-L59 -> 157.66071 | O59: =G59/$B$3^2 -> 35 | P59: =G59*I59/$B$3/($B$2*9.81*0.5) -> -0.029561672
B60: 50 | C60: 60110102 | D60: 120 | E60: 8 | F60: 80 | G60: 40 | H60: =$B$2/2*9.81*$B$3/G60 -> 137.95312 | I60: =F60-H60 -> -57.953125 | J60: =I60-$M$4 -> -133.64513 | K60: =IF(J60<=0,"KO","OK") -> KO | L60: =D60-H60 -> -17.953125 | M60: =D60-L60 -> 137.95312 | O60: =G60/$B$3^2 -> 40 | P60: =G60*I60/$B$3/($B$2*9.81*0.5) -> -0.42009288
B61: 51 | C61: 60110104 | D61: 140 | E61: 8.5 | F61: 90 | G61: 40 | H61: =$B$2/2*9.81*$B$3/G61 -> 137.95312 | I61: =F61-H61 -> -47.953125 | J61: =I61-$M$4 -> -123.64513 | K61: =IF(J61<=0,"KO","OK") -> KO | L61: =D61-H61 -> 2.046875 | M61: =D61-L61 -> 137.95312 | O61: =G61/$B$3^2 -> 40 | P61: =G61*I61/$B$3/($B$2*9.81*0.5) -> -0.34760449
B62: 52 | C62: 60110106 | D62: 170 | E62: 9 | F62: 108 | G62: 40 | H62: =$B$2/2*9.81*$B$3/G62 -> 137.95312 | I62: =F62-H62 -> -29.953125 | J62: =I62-$M$4 -> -105.64513 | K62: =IF(J62<=0,"KO","OK") -> KO | L62: =D62-H62 -> 32.046875 | M62: =D62-L62 -> 137.95312 | O62: =G62/$B$3^2 -> 40 | P62: =G62*I62/$B$3/($B$2*9.81*0.5) -> -0.21712538
B63: 53 | C63: 60110013 | D63: 200 | E63: 9.5 | F63: 121 | G63: 40 | H63: =$B$2/2*9.81*$B$3/G63 -> 137.95312 | I63: =F63-H63 -> -16.953125 | J63: =I63-$M$4 -> -92.645125 | K63: =IF(J63<=0,"KO","OK") -> KO | L63: =D63-H63 -> 62.046875 | M63: =D63-L63 -> 137.95312 | O63: =G63/$B$3^2 -> 40 | P63: =G63*I63/$B$3/($B$2*9.81*0.5) -> -0.12289047
B64: 54 | C64: 60110056 | D64: 250 | E64: 10 | F64: 154 | G64: 40 | H64: =$B$2/2*9.81*$B$3/G64 -> 137.95312 | I64: =F64-H64 -> 16.046875 | J64: =I64-$M$4 -> -59.645125 | K64: =IF(J64<=0,"KO","OK") -> KO | L64: =D64-H64 -> 112.04688 | M64: =D64-L64 -> 137.95312 | O64: =G64/$B$3^2 -> 40 | P64: =G64*I64/$B$3/($B$2*9.81*0.5) -> 0.11632121
B65: 55 | C65: 60110094 | D65: 290 | E65: 10.5 | F65: 177 | G65: 40 | H65: =$B$2/2*9.81*$B$3/G65 -> 137.95312 | I65: =F65-H65 -> 39.046875 | J65: =I65-$M$4 -> -36.645125 | K65: =IF(J65<=0,"KO","OK") -> KO | L65: =D65-H65 -> 152.04688 | M65: =D65-L65 -> 137.95312 | O65: =G65/$B$3^2 -> 40 | P65: =G65*I65/$B$3/($B$2*9.81*0.5) -> 0.28304451
B66: 56 | C66: 60110072 | D66: 250 | E66: 10.5 | F66: 145 | G66: 45 | H66: =$B$2/2*9.81*$B$3/G66 -> 122.625 | I66: =F66-H66 -> 22.375 | J66: =I66-$M$4 -> -53.317 | K66: =IF(J66<=0,"KO","OK") -> KO | L66: =D66-H66 -> 127.375 | M66: =D66-L66 -> 122.625 | O66: =G66/$B$3^2 -> 45 | P66: =G66*I66/$B$3/($B$2*9.81*0.5) -> 0.18246687
... B156: 146 | C156: 60110089 | D156: 100 | E156: 14 | F156: 37 | G156: 340 | H156: =$B$2/2*9.81*$B$3/G156 -> 16.229779 | I156: =F156-H156 -> 20.770221 | J156: =I156-$M$4 -> -54.921779 | K156: =IF(J156<=0,"KO","OK") -> KO | L156: =D156-H156 -> 83.770221 | M156: =D156-L156 -> 16.229779 | O156: =G156/$B$3^2 -> 340 | P156: =G156*I156/$B$3/($B$2*9.81*0.5) -> 1.2797599
A157: Inner diameter 71mm | B157: 147 | C157: 60110125 | D157: 250 | E157: 12 | F157: 148 | G157: 60 | H157: =$B$2/2*9.81*$B$3/G157 -> 91.96875 | I157: =F157-H157 -> 56.03125 | J157: =I157-$M$4 -> -19.66075 | K157: =IF(J157<=0,"KO","OK") -> KO | L157: =D157-H157 -> 158.03125 | M157: =D157-L157 -> 91.96875 | O157: =G157/$B$3^2 -> 60 | P157: =G157*I157/$B$3/($B$2*9.81*0.5) -> 0.60924227
B158: 148 | C158: 60110124 | D158: 200 | E158: 11.75 | F158: 117 | G158: 70 | H158: =$B$2/2*9.81*$B$3/G158 -> 78.830357 | I158: =F158-H158 -> 38.169643 | J158: =I158-$M$4 -> -37.522357 | K158: =IF(J158<=0,"KO","OK") -> KO | L158: =D158-H158 -> 121.16964 | M158: =D158-L158 -> 78.830357 | O158: =G158/$B$3^2 -> 70 | P158: =G158*I158/$B$3/($B$2*9.81*0.5) -> 0.4841998
B159: 149 | C159: 60110126 | D159: 250 | E159: 12.5 | F159: 145 | G159: 70 | H159: =$B$2/2*9.81*$B$3/G159 -> 78.830357 | I159: =F159-H159 -> 66.169643 | J159: =I159-$M$4 -> -9.5223571 | K159: =IF(J159<=0,"KO","OK") -> KO | L159: =D159-H159 -> 171.16964 | M159: =D159-L159 -> 78.830357 | O159: =G159/$B$3^2 -> 70 | P159: =G159*I159/$B$3/($B$2*9.81*0.5) -> 0.83939291
B160: 150 | C160: 60110146 | D160: 170 | E160: 11.9 | F160: 100 | G160: 80 | H160: =$B$2/2*9.81*$B$3/G160 -> 68.976562 | I160: =F160-H160 -> 31.023438 | J160: =I160-$M$4 -> -44.668563 | K160: =IF(J160<=0,"KO","OK") -> KO | L160: =D160-H160 -> 101.02344 | M160: =D160-L160 -> 68.976562 | O160: =G160/$B$3^2 -> 80 | P160: =G160*I160/$B$3/($B$2*9.81*0.5) -> 0.44976781
...

Sheet front damper
C2: Strut housing length C [mm] | D2: Stroke B [mm] | F2: NO HLS | N2: Color code | P2: Helper springs
C3: 150 | D3: 75 | F3: L_actuator | G3: 0 | H3: [mm] | N3: Formula result | P3: Inner diameter 51 mm
C4: 175 | D4: 100 | F4: Stroke | G4: 0 | H4: [mm] | N4: Input data | P4: Spring rate [N/mm] | Q4: Free length [mm] | R4: Max spring travel [mm] | S4: Part - No.
C5: 200 | D5: 125 | N5: Constrained input data | P5: 5 | Q5: 80 | R5: 55 | S5: 60110144
C6: 225 | D6: 150 | F6: NO HLS | N6: Result = OK | P6: 20 | Q6: 60 | R6: 46 | S6: 60110028
C7: 250 | D7: =C7-C3+D3 -> 175 | F7: L_actuator | G7: 0 | H7: [mm] | N7: Result = KO | P7: Inner diameter 61 mm
C8: 260 | D8: 185 | F8: Stroke | G8: 0 | H8: [mm] | P8: 3 | Q8: 80 | R8: 68 | S8: 60110100
C9: 300 | D9: 225 | P9: 10 | Q9: 80 | R9: 55 | S9: 60110028
P10: 20 | Q10: 80 | R10: 45 | S10: 60110005
C11: Other dimensions [mm] | G11: Spring travel | P11: 40 | Q11: 60 | R11: 44 | S11: 60110080
C12: A | D12: 77.5 | F12: 1 | G12: Travel | H12: Bump | I12: Rebound | P12: 50 | Q12: 60 | R12: 43 | S12: 60110081
C13: D | D13: 30 | F13: =VLOOKUP($F$12,'front wheel travel'!$A$14:$E$16,2) -> Race | G13: =H13+I13 -> 143.6 | H13: ='front spring'!M4 -> 75.692 | I13: ='front spring'!J8-'front spring'!G8 -> 67.908 | P13: 60 | Q13: 60 | R13: 36 | S13: 60110092
C14: E | D14: 35.5 | P14: Inner diameter 71 mm
C15: F | D15: 13 | P15: 15 | Q15: 80 | R15: 53 | S15: 60110122
C16: G | D16: =3 -> 3
C17: H | D17: 11.5
F21: REBOUND TRAVEL [mm] | G21: Coilover desired static length [mm] | H21: BUMP TRAVEL [mm] | J21: Coilover pack | N21: STOPS LENGTH | Q21: correction
D22: D | E22: =$D$13 -> 30 | F22: =SUM(E22:E25)-G23 -> 82.9 | N22: Bump | O22: =H24-H13 -> 16.408 | P22: [mm]
D23: C | E23: 250 | G23: 449.6 | J23: H | K23: =$D$17 -> 11.5 | L23: [mm] | N23: Rebound | O23: =F22-I13 -> 14.992 | P23: [mm]
D24: B | E24: =VLOOKUP($E$23,$C$3:$D$9,2) -> 175 | H24: =E24-F22 -> 92.1 | J24: Spring static length | K24: =$H$30 -> 139.6375 | L24: [mm]
D25: A | E25: =$D$12 -> 77.5 | J25: G | K25: =$D$16 -> 3 | L25: [mm] | N25: FULL REBOUND SPRING CHECK
F26: =IF(F22>=I13,"OK","KO") -> OK | H26: =IF(H24>=H13,"OK","KO") -> OK | J26: Helper static legth | K26: =Q9-R9 -> 25 | L26: [mm] | N26: Coilover pack length in max rebound - allowed by strut | O26: =K30+F22 -> 275.0375 | P26: [mm]
J27: L_actuator | K27: =$G$3 -> 0 | L27: [mm] | N27: Coilover pack free length | O27: =E30+K28+Q9+K27+K25+K23 -> 357.5 | P27: [mm]
B28: SELECTED SPRINGS | J28: F | K28: =$D$15 -> 13 | L28: [mm] | N28: Coilover pack length in max rebound - considering rebound stop | O28: =O26-O23 -> 260.0455 | P28: [mm]
B29: Index | C29: Part-No. | D29: Spring rate [N/mm] | E29: Free length [mm] | F29: Max spring travel Sn [mm] | G29: Spring static travel [mm] | H29: Static spring length | N29: Spring compression needed when assembling | O29: =O27-(K31+I13) -> -17.008 | P29: [mm]
B30: 60 | C30: =VLOOKUP($B30,'front spring'!$B$11:$M$166,2) -> 60110073 | D30: =VLOOKUP($B30,'front spring'!$B$11:$M$166,6) -> 50 | E30: =VLOOKUP($B30,'front spring'!$B$11:$M$166,3) -> 250 | F30: =VLOOKUP($B30,'front spring'!$B$11:$M$166,5) -> 144 | G30: =VLOOKUP($B30,'front spring'!$B$11:$M$166,7) -> 110.3625 | H30: =VLOOKUP($B30,'front spring'!$B$11:$M$166,11) -> 139.6375 | J30: Coilover static pack length | K30: =SUM(K23:K28) -> 192.1375 | L30: [mm] | O30: Rebound | Q30: Bump | R30: tot
B31: 70 | C31: =VLOOKUP($B31,'front spring'!$B$11:$M$166,2) -> 60110074 | D31: =VLOOKUP($B31,'front spring'!$B$11:$M$166,6) -> 60 | E31: =VLOOKUP($B31,'front spring'!$B$11:$M$166,3) -> 250 | F31: =VLOOKUP($B31,'front spring'!$B$11:$M$166,5) -> 143 | G31: =VLOOKUP($B31,'front spring'!$B$11:$M$166,7) -> 91.96875 | H31: =VLOOKUP($B31,'front spring'!$B$11:$M$166,11) -> 158.03125 | J31: Max static pack length allowed | K31: =$G$23-$D$12-$D$13-$D$14 -> 306.6 | L31: [mm] | N31: Corsa dell'ammortizzatore | O31: =F22 -> 82.9 | Q31: =H24 -> 92.1 | R31: =Q31+O31 -> 175
B32: 78 | C32: =VLOOKUP($B32,'front spring'!$B$11:$M$166,2) -> 60110075 | D32: =VLOOKUP($B32,'front spring'!$B$11:$M$166,6) -> 70 | E32: =VLOOKUP($B32,'front spring'!$B$11:$M$166,3) -> 250 | F32: =VLOOKUP($B32,'front spring'!$B$11:$M$166,5) -> 138 | G32: =VLOOKUP($B32,'front spring'!$B$11:$M$166,7) -> 78.830357 | H32: =VLOOKUP($B32,'front spring'!$B$11:$M$166,11) -> 171.16964 | J32: Preload decrease adjustment [R] | K32: =K31-K30 -> 114.4625 | L32: [mm] | N32: Corsa della molla | O32: =G30 -> 110.3625 | Q32: =F30-G30 -> 33.6375 | R32: =Q32+O32 -> 144
B33: 86 | C33: =VLOOKUP($B33,'front spring'!$B$11:$M$166,2) -> 60110090 | D33: =VLOOKUP($B33,'front spring'!$B$11:$M$166,6) -> 80 | E33: =VLOOKUP($B33,'front spring'!$B$11:$M$166,3) -> 250 | F33: =VLOOKUP($B33,'front spring'!$B$11:$M$166,5) -> 133 | G33: =VLOOKUP($B33,'front spring'!$B$11:$M$166,7) -> 68.976562 | H33: =VLOOKUP($B33,'front spring'!$B$11:$M$166,11) -> 181.02344 | J33: Preload decrease adjustment | K33: =D30*K32 -> 5723.125 | L33: [N] | N33: Scuotimento della ruota in funzione dello scuotimento della molla | O33: =O32*O35 -> 110.3625 | P33: =IF(O33<=40,"KO","OK") -> OK | Q33: =Q32*O35 -> 33.6375 | R33: =IF(Q33<=60,"KO","OK") -> KO
B34: 92 | C34: =VLOOKUP($B34,'front spring'!$B$11:$M$166,2) -> 60110091 | D34: =VLOOKUP($B34,'front spring'!$B$11:$M$166,6) -> 90 | E34: =VLOOKUP($B34,'front spring'!$B$11:$M$166,3) -> 250 | F34: =VLOOKUP($B34,'front spring'!$B$11:$M$166,5) -> 133 | G34: =VLOOKUP($B34,'front spring'!$B$11:$M$166,7) -> 61.3125 | H34: =VLOOKUP($B34,'front spring'!$B$11:$M$166,11) -> 188.6875 | J34: Preload increase adjustment | K34: =E23-D14-K32-D15-G3-G4 -> 87.0375 | L34: [mm] | N34: Scuotimento della ruota in funzione dello scuotimento dell'ammortizzatore | O34: =O35*O31 -> 82.9 | Q34: =O35*Q31 -> 92.1
J35: Preload increase adjustment | K35: =D30*K34 -> 4351.875 | L35: [N] | N35: Motion ratio | O35: ='front motion ratio'!C15 -> 1

Sheet rear motion ratio
B2: SCG004C | F2: P4/5 Competizione m | J2: Color code
B3: Massa Veicolo | C3: ='front motion ratio'!C3 -> 2250 | D3: [kg] | F3: Massa Veicolo | G3: 1350 | H3: [kg] | J3: Formula result
B4: Ripartizione massa ant | C4: 0.5 | F4: Ripartizione massa ant | G4: 0.46 | J4: Input data
B5: Ripartizione massa post | C5: 0.5 | F5: Ripartizione massa post | G5: 0.54 | J5: Constrained input data
B6: Massa passeggeri | C6: ='front motion ratio'!C6 -> 0 | D6: [kg] | F6: Massa passeggeri | G6: 75 | H6: [kg] | J6: Result = OK
B7: Massa carburante | C7: ='front motion ratio'!C7 -> 0 | D7: [kg] | F7: Massa carburante | G7: =113*0.72/2 -> 40.68 | H7: [kg] | J7: Result = KO
B9: Massa totale | C9: =C3+C6+C7 -> 2250 | D9: [kg] | F9: Massa totale | G9: =G3+G6+G7 -> 1465.68 | H9: [kg] | J9: Static damper ratio
B10: Massa assale ant | C10: =C9*C4-C12 -> 985 | D10: [kg] | F10: Massa assale ant | G10: =G9*G4 -> 674.2128 | H10: [kg] | J10: Race | K10: 1 | L10: =C15 -> 1
B11: Massa assale post | C11: =C9*C5-C13 -> 985 | D11: [kg] | F11: Massa assale post | G11: =G9*G5 -> 791.4672 | H11: [kg] | J11: Street | K11: 2 | L11: =+L10 -> 1
B12: Massa non sospesa assale ant | C12: 140 | D12: [kg] | E12: guess | F12: Massa non sospesa assale ant | G12: 60 | H12: [kg] | J12: Lift | K12: 3 | L12: =+L10 -> 1
B13: Massa non sospesa assale post | C13: 140 | D13: [kg] | E13: guess | F13: Massa non sospesa assale post | G13: 60 | H13: [kg]
B15: Damper ratio (Standard) | C15: 1 | F15: Damper ratio (Highway) | G15: 1.68 | J15: KW advised spring rates
B16: Frequenza moti di cassa (Standard) | C16: 1.7 | D16: [Hz] | F16: Frequenza moti di cassa | G16: 2.45 | H16: [Hz] | J16: Front | K16: 140 | L16: [N/mm]
B17: Rigidezza verticale pneumatico | C17: 250 | D17: [N/mm] | F17: Rigidezza verticale pneumatico | G17: 339 | H17: [N/mm] | J17: Rear | K17: 150 | L17: [N/mm]
B19: Rigidezza molla posteriore (1 g.d.l.) | C19: =2*(PI()*C16*C15)^2*(C11-C13)/1000 -> 48.204135 | D19: [N/mm] | F19: Rigidezza molla posteriore (1 g.d.l.) | G19: =2*(PI()*G16*G15)^2*G11/1000 -> 264.67529 | H19: [N/mm]
B20: Rigidezza molla posteriore (2 g.d.l.) | C20: =(2*(PI()*C16*C15)^2*(C11-C13)*C17*1000/(C17*1000-2*PI()^2*C16^2*(C11-C13)))/1000 -> 59.718933 | D20: [N/mm] | F20: Rigidezza molla posteriore (2 g.d.l.) | G20: =(2*(PI()*G16*G15)^2*(G11-G13)*G17*1000/(G17*1000-2*PI()^2*G16^2*(G11-G13)))/1000 -> 328.62607 | H20: [N/mm]
B22: Rigidezza molla posteriore (2 g.d.l.) | C22: 70 | D22: [N/mm] | F22: Rigidezza molla posteriore (2 g.d.l.) | G22: 330 | H22: [N/mm]
B23: Frequenza massa non sospesa post. | C23: =1/(2*PI())*SQRT(1000*(C22/C15^2+C17)/(C13*0.5)) -> 10.760838 | D23: [Hz] | F23: Frequenza massa non sospesa post. | G23: =1/(2*PI())*SQRT(1000*(G22/G15^2+G17)/(G13*0.5)) -> 19.620256 | H23: [Hz]
B24: Rigidezza a terra post (2 g.d.l.) | C24: =((C22/C15^2)^-1+C17^-1)^-1 -> 54.6875 | D24: [N/mm] | F24: Rigidezza a terra (2 g.d.l.) | G24: =((G22/G15^2)^-1+G17^-1)^-1 -> 86.937019 | H24: [N/mm]
B25: Rigidezza a terra (1 g.d.l.) | C25: =C22/C15^2 -> 70 | D25: [N/mm] | F25: Rigidezza a terra (1 g.d.l.) | G25: =G22/G15^2 -> 116.92177 | H25: [N/mm]
B27: Setup name | C27: Soft
B28: Spring | C28: 230 | D28: N/mm
B29: Ground rate | C29: 106 | D29: N/mm
B30: 1-dof ride frequency | C30: 3.1 | D30: Hz
B31: 2-dof ride frequency | C31: 2.69 | D31: Hz
B33: Modded to subtract unsprung mass

Sheet rear wheel travel
G1: Ride height | M1: Color code
B2: Max wheel center travel | C2: =C3+C4 -> 90 | D2: [mm] | E2: Unused travel [mm] | H2: Delta height | I2: d-race | M2: Formula result
B3: Rebound travel | C3: 30 | D3: [mm] | E3: 0 | G3: Race | H3: 0 | I3: 0 | K3: [mm] | M3: Input data
B4: Bump travel | C4: 60 | D4: [mm] | E4: 0 | G4: Street | H4: 0 | I4: =I3+H4 -> 0 | K4: [mm] | M4: Constrained input data
G5: Lift | H5: 0 | I5: =I4+H5 -> 0 | K5: [mm] | M5: Result = OK
B6: D_tyre_road | C6: ='front wheel travel'!C7 -> 704.9 | D6: [mm] | M6: Result = KO
B7: D_tyre_race | C7: ='front wheel travel'!C8 -> 640 | D7: [mm] | G7: Susp. Point vertical translation | H7: =0+H8 -> 0 | I7: [mm]
B8: delta_tyre_radius | C8: =(C6-C7)/2 -> 32.45 | D8: [mm] | G8: Wheel center pre-bump in std. static condition | H8: 0 | I8: [mm]
C11: Wheel center travel | H11: Spring travel
C12: Travel | D12: Bump | E12: Rebound | H12: Travel | I12: Bump | J12: Rebound
A13: 1 | B13: Race | C13: =C14 -> 90 | D13: =C13-E13 -> 60 | E13: =E14+H4 -> 30 | G13: Highway | H13: =C13/'rear motion ratio'!$C$15 -> 90 | I13: =D13/'rear motion ratio'!$C$15 -> 60 | J13: =E13/'rear motion ratio'!$C$15 -> 30
A14: 2 | B14: Street | C14: =D14+E14 -> 90 | D14: =C4-E4-H8 -> 60 | E14: =E15 -> 30 | G14: Standard | H14: =C14/'rear motion ratio'!$C$15 -> 90 | I14: =D14/'rear motion ratio'!$C$15 -> 60 | J14: =E14/'rear motion ratio'!$C$15 -> 30
A15: 3 | B15: Lift | C15: =D15+E15 -> 90 | D15: =C2-E3-E4-E15 -> 60 | E15: =C3-E3+H8-H5 -> 30 | G15: Offroad | H15: =C15/'rear motion ratio'!$C$15 -> 90 | I15: =D15/'rear motion ratio'!$C$15 -> 60 | J15: =E15/'rear motion ratio'!$C$15 -> 30

Sheet rear spring
A2: Rear axle mass | B2: ='rear motion ratio'!C11 -> 985 | C2: [kg] | G2: Wheel center travel | L2: Spring travel | Q2: Color code
A3: Damper ratio | B3: =VLOOKUP(E4,'rear motion ratio'!$K$10:$L$13,2,FALSE) -> 1 | G3: Travel | H3: Bump | I3: Rebound | L3: Travel | M3: Bump | N3: Rebound | Q3: Formula result
E4: 1 | F4: =VLOOKUP($E$4,'rear wheel travel'!$A$13:$E$15,2) -> Race | G4: =VLOOKUP($E$4,'rear wheel travel'!$A$13:$E$15,3) -> 90 | H4: =VLOOKUP($E$4,'rear wheel travel'!$A$13:$E$15,4) -> 60 | I4: =VLOOKUP($E$4,'rear wheel travel'!$A$13:$E$15,5) -> 30 | K4: =F4 -> Race | L4: =I8-H8 -> 91.4 | M4: =G8-H8 -> 62.2 | N4: =I8-G8 -> 29.2 | Q4: Input data
Q5: Constrained input data
G6: Damper length [mm] from CAD | Q6: Result = OK
G7: Static | H7: Bump (60) | I7: Rebound (-30) | J7: Rebound (-60) | Q7: Result = KO
G8: 400.8 | H8: 338.6 | I8: 430 | J8: 458.5 | Q8: From multibody
B10: Index | C10: Part-No. | D10: Free length [mm] | E10: Wire diameter [mm] | F10: Max spring travel Sn [mm] | G10: Spring rate [N/mm] | H10: Spring static travel [mm] | I10: Bump travel | J10: Spring travel after max bump | K10: OK/KO | L10: Static spring length | M10: Rebound travel | O10: Rigidezza a terra corrispettiva 1 g.d.l. [N/mm] | P10: G su molla @ max bump
A11: Inner diameter 51mm | B11: 1 | C11: 60110178 | D11: 210 | E11: 8.25 | F11: 128 | G11: 30 | H11: =$B$2/2*9.81*$B$3/G11 -> 161.0475 | I11: =F11-H11 -> -33.0475 | J11: =I11-$M$4 -> -95.2475 | K11: =IF(J11<=0,"KO","OK") -> KO | L11: =D11-H11 -> 48.9525 | M11: =D11-L11 -> 161.0475 | O11: =G11/$B$3^2 -> 30 | P11: =G11*I11/$B$3/($B$2*9.81*0.5) -> -0.20520343
B12: 2 | C12: 60110132 | D12: 170 | E12: 8.25 | F12: 103 | G12: 40 | H12: =$B$2/2*9.81*$B$3/G12 -> 120.78563 | I12: =F12-H12 -> -17.785625 | J12: =I12-$M$4 -> -79.985625 | K12: =IF(J12<=0,"KO","OK") -> KO | L12: =D12-H12 -> 49.214375 | M12: =D12-L12 -> 120.78563 | O12: =G12/$B$3^2 -> 40 | P12: =G12*I12/$B$3/($B$2*9.81*0.5) -> -0.14724952
B13: 3 | C13: 60110133 | D13: 190 | E13: 8.75 | F13: 108 | G13: 40 | H13: =$B$2/2*9.81*$B$3/G13 -> 120.78563 | I13: =F13-H13 -> -12.785625 | J13: =I13-$M$4 -> -74.985625 | K13: =IF(J13<=0,"KO","OK") -> KO | L13: =D13-H13 -> 69.214375 | M13: =D13-L13 -> 120.78563 | O13: =G13/$B$3^2 -> 40 | P13: =G13*I13/$B$3/($B$2*9.81*0.5) -> -0.10585386
B14: 4 | C14: 60110134 | D14: 230 | E14: 9.25 | F14: 127 | G14: 40 | H14: =$B$2/2*9.81*$B$3/G14 -> 120.78563 | I14: =F14-H14 -> 6.214375 | J14: =I14-$M$4 -> -55.985625 | K14: =IF(J14<=0,"KO","OK") -> KO | L14: =D14-H14 -> 109.21437 | M14: =D14-L14 -> 120.78563 | O14: =G14/$B$3^2 -> 40 | P14: =G14*I14/$B$3/($B$2*9.81*0.5) -> 0.051449624
B15: 5 | C15: 60110147 | D15: 290 | E15: 9.75 | F15: 162 | G15: 40 | H15: =$B$2/2*9.81*$B$3/G15 -> 120.78563 | I15: =F15-H15 -> 41.214375 | J15: =I15-$M$4 -> -20.985625 | K15: =IF(J15<=0,"KO","OK") -> KO | L15: =D15-H15 -> 169.21437 | M15: =D15-L15 -> 120.78563 | O15: =G15/$B$3^2 -> 40 | P15: =G15*I15/$B$3/($B$2*9.81*0.5) -> 0.34121921
B16: 6 | C16: 60110135 | D16: 310 | E16: 10 | F16: 165 | G16: 40 | H16: =$B$2/2*9.81*$B$3/G16 -> 120.78563 | I16: =F16-H16 -> 44.214375 | J16: =I16-$M$4 -> -17.985625 | K16: =IF(J16<=0,"KO","OK") -> KO | L16: =D16-H16 -> 189.21437 | M16: =D16-L16 -> 120.78563 | O16: =G16/$B$3^2 -> 40 | P16: =G16*I16/$B$3/($B$2*9.81*0.5) -> 0.3660566
B17: 7 | C17: 60110111 | D17: 140 | E17: 8.5 | F17: 81 | G17: 50 | H17: =$B$2/2*9.81*$B$3/G17 -> 96.6285 | I17: =F17-H17 -> -15.6285 | J17: =I17-$M$4 -> -77.8285 | K17: =IF(J17<=0,"KO","OK") -> KO | L17: =D17-H17 -> 43.3715 | M17: =D17-L17 -> 96.6285 | O17: =G17/$B$3^2 -> 50 | P17: =G17*I17/$B$3/($B$2*9.81*0.5) -> -0.161738
B18: 8 | C18: 60110131 | D18: 170 | E18: 9 | F18: 92 | G18: 50 | H18: =$B$2/2*9.81*$B$3/G18 -> 96.6285 | I18: =F18-H18 -> -4.6285 | J18: =I18-$M$4 -> -66.8285 | K18: =IF(J18<=0,"KO","OK") -> KO | L18: =D18-H18 -> 73.3715 | M18: =D18-L18 -> 96.6285 | O18: =G18/$B$3^2 -> 50 | P18: =G18*I18/$B$3/($B$2*9.81*0.5) -> -0.047899947
B19: 9 | C19: 60110136 | D19: 190 | E19: 9.25 | F19: 105 | G19: 50 | H19: =$B$2/2*9.81*$B$3/G19 -> 96.6285 | I19: =F19-H19 -> 8.3715 | J19: =I19-$M$4 -> -53.8285 | K19: =IF(J19<=0,"KO","OK") -> KO | L19: =D19-H19 -> 93.3715 | M19: =D19-L19 -> 96.6285 | O19: =G19/$B$3^2 -> 50 | P19: =G19*I19/$B$3/($B$2*9.81*0.5) -> 0.08663593
B20: 10 | C20: 60110175 | D20: 210 | E20: 9.5 | F20: 118 | G20: 50 | H20: =$B$2/2*9.81*$B$3/G20 -> 96.6285 | I20: =F20-H20 -> 21.3715 | J20: =I20-$M$4 -> -40.8285 | K20: =IF(J20<=0,"KO","OK") -> KO | L20: =D20-H20 -> 113.3715 | M20: =D20-L20 -> 96.6285 | O20: =G20/$B$3^2 -> 50 | P20: =G20*I20/$B$3/($B$2*9.81*0.5) -> 0.22117181
B21: 11 | C21: 60110137 | D21: 230 | E21: 9.75 | F21: 125 | G21: 50 | H21: =$B$2/2*9.81*$B$3/G21 -> 96.6285 | I21: =F21-H21 -> 28.3715 | J21: =I21-$M$4 -> -33.8285 | K21: =IF(J21<=0,"KO","OK") -> KO | L21: =D21-H21 -> 133.3715 | M21: =D21-L21 -> 96.6285 | O21: =G21/$B$3^2 -> 50 | P21: =G21*I21/$B$3/($B$2*9.81*0.5) -> 0.2936142
B22: 12 | C22: 60110148 | D22: 290 | E22: 10.5 | F22: 150 | G22: 50 | H22: =$B$2/2*9.81*$B$3/G22 -> 96.6285 | I22: =F22-H22 -> 53.3715 | J22: =I22-$M$4 -> -8.8285 | K22: =IF(J22<=0,"KO","OK") -> KO | L22: =D22-H22 -> 193.3715 | M22: =D22-L22 -> 96.6285 | O22: =G22/$B$3^2 -> 50 | P22: =G22*I22/$B$3/($B$2*9.81*0.5) -> 0.55233704
B23: 13 | C23: 60110138 | D23: 310 | E23: 10.75 | F23: 155 | G23: 50 | H23: =$B$2/2*9.81*$B$3/G23 -> 96.6285 | I23: =F23-H23 -> 58.3715 | J23: =I23-$M$4 -> -3.8285 | K23: =IF(J23<=0,"KO","OK") -> KO | L23: =D23-H23 -> 213.3715 | M23: =D23-L23 -> 96.6285 | O23: =G23/$B$3^2 -> 50 | P23: =G23*I23/$B$3/($B$2*9.81*0.5) -> 0.60408161
... B53: 43 | C53: 60110165 | D53: 130 | E53: 14 | F53: 49 | G53: 350 | H53: =$B$2/2*9.81*$B$3/G53 -> 13.804071 | I53: =F53-H53 -> 35.195929 | J53: =I53-$M$4 -> -27.004071 | K53: =IF(J53<=0,"KO","OK") -> KO | L53: =D53-H53 -> 116.19593 | M53: =D53-L53 -> 13.804071 | O53: =G53/$B$3^2 -> 350 | P53: =G53*I53/$B$3/($B$2*9.81*0.5) -> 2.5496774
A54: Inner diameter 61mm | B54: 44 | C54: 60110053 | D54: 250 | E54: 8.75 | F54: 165 | G54: 25 | H54: =$B$2/2*9.81*$B$3/G54 -> 193.257 | I54: =F54-H54 -> -28.257 | J54: =I54-$M$4 -> -90.457 | K54: =IF(J54<=0,"KO","OK") -> KO | L54: =D54-H54 -> 56.743 | M54: =D54-L54 -> 193.257 | O54: =G54/$B$3^2 -> 25 | P54: =G54*I54/$B$3/($B$2*9.81*0.5) -> -0.14621463
B55: 45 | C55: 60110105 | D55: 170 | E55: 8.25 | F55: 110 | G55: 30 | H55: =$B$2/2*9.81*$B$3/G55 -> 161.0475 | I55: =F55-H55 -> -51.0475 | J55: =I55-$M$4 -> -113.2475 | K55: =IF(J55<=0,"KO","OK") -> KO | L55: =D55-H55 -> 8.9525 | M55: =D55-L55 -> 161.0475 | O55: =G55/$B$3^2 -> 30 | P55: =G55*I55/$B$3/($B$2*9.81*0.5) -> -0.3169717
B56: 46 | C56: 60110009 | D56: 200 | E56: 9.25 | F56: 113 | G56: 30 | H56: =$B$2/2*9.81*$B$3/G56 -> 161.0475 | I56: =F56-H56 -> -48.0475 | J56: =I56-$M$4 -> -110.2475 | K56: =IF(J56<=0,"KO","OK") -> KO | L56: =D56-H56 -> 38.9525 | M56: =D56-L56 -> 161.0475 | O56: =G56/$B$3^2 -> 30 | P56: =G56*I56/$B$3/($B$2*9.81*0.5) -> -0.29834366
B57: 47 | C57: 60110051 | D57: 200 | E57: 8.75 | F57: 128 | G57: 30 | H57: =$B$2/2*9.81*$B$3/G57 -> 161.0475 | I57: =F57-H57 -> -33.0475 | J57: =I57-$M$4 -> -95.2475 | K57: =IF(J57<=0,"KO","OK") -> KO | L57: =D57-H57 -> 38.9525 | M57: =D57-L57 -> 161.0475 | O57: =G57/$B$3^2 -> 30 | P57: =G57*I57/$B$3/($B$2*9.81*0.5) -> -0.20520343
B58: 48 | C58: 60110010 | D58: 250 | E58: 9.25 | F58: 160 | G58: 30 | H58: =$B$2/2*9.81*$B$3/G58 -> 161.0475 | I58: =F58-H58 -> -1.0475 | J58: =I58-$M$4 -> -63.2475 | K58: =IF(J58<=0,"KO","OK") -> KO | L58: =D58-H58 -> 88.9525 | M58: =D58-L58 -> 161.0475 | O58: =G58/$B$3^2 -> 30 | P58: =G58*I58/$B$3/($B$2*9.81*0.5) -> -0.0065042922
B59: 49 | C59: 60110055 | D59: 250 | E59: 9.75 | F59: 153 | G59: 35 | H59: =$B$2/2*9.81*$B$3/G59 -> 138.04071 | I59: =F59-H59 -> 14.959286 | J59: =I59-$M$4 -> -47.240714 | K59: =IF(J59<=0,"KO","OK") -> KO | L59: =D59-H59 -> 111.95929 | M59: =D59-L59 -> 138.04071 | O59: =G59/$B$3^2 -> 35 | P59: =G59*I59/$B$3/($B$2*9.81*0.5) -> 0.10836865
B60: 50 | C60: 60110102 | D60: 120 | E60: 8 | F60: 80 | G60: 40 | H60: =$B$2/2*9.81*$B$3/G60 -> 120.78563 | I60: =F60-H60 -> -40.785625 | J60: =I60-$M$4 -> -102.98562 | K60: =IF(J60<=0,"KO","OK") -> KO | L60: =D60-H60 -> -0.785625 | M60: =D60-L60 -> 120.78563 | O60: =G60/$B$3^2 -> 40 | P60: =G60*I60/$B$3/($B$2*9.81*0.5) -> -0.33766953
B61: 51 | C61: 60110104 | D61: 140 | E61: 8.5 | F61: 90 | G61: 40 | H61: =$B$2/2*9.81*$B$3/G61 -> 120.78563 | I61: =F61-H61 -> -30.785625 | J61: =I61-$M$4 -> -92.985625 | K61: =IF(J61<=0,"KO","OK") -> KO | L61: =D61-H61 -> 19.214375 | M61: =D61-L61 -> 120.78563 | O61: =G61/$B$3^2 -> 40 | P61: =G61*I61/$B$3/($B$2*9.81*0.5) -> -0.25487822
B62: 52 | C62: 60110106 | D62: 170 | E62: 9 | F62: 108 | G62: 40 | H62: =$B$2/2*9.81*$B$3/G62 -> 120.78563 | I62: =F62-H62 -> -12.785625 | J62: =I62-$M$4 -> -74.985625 | K62: =IF(J62<=0,"KO","OK") -> KO | L62: =D62-H62 -> 49.214375 | M62: =D62-L62 -> 120.78563 | O62: =G62/$B$3^2 -> 40 | P62: =G62*I62/$B$3/($B$2*9.81*0.5) -> -0.10585386
B63: 53 | C63: 60110013 | D63: 200 | E63: 9.5 | F63: 121 | G63: 40 | H63: =$B$2/2*9.81*$B$3/G63 -> 120.78563 | I63: =F63-H63 -> 0.214375 | J63: =I63-$M$4 -> -61.985625 | K63: =IF(J63<=0,"KO","OK") -> KO | L63: =D63-H63 -> 79.214375 | M63: =D63-L63 -> 120.78563 | O63: =G63/$B$3^2 -> 40 | P63: =G63*I63/$B$3/($B$2*9.81*0.5) -> 0.0017748387
B64: 54 | C64: 60110056 | D64: 250 | E64: 10 | F64: 154 | G64: 40 | H64: =$B$2/2*9.81*$B$3/G64 -> 120.78563 | I64: =F64-H64 -> 33.214375 | J64: =I64-$M$4 -> -28.985625 | K64: =IF(J64<=0,"KO","OK") -> KO | L64: =D64-H64 -> 129.21437 | M64: =D64-L64 -> 120.78563 | O64: =G64/$B$3^2 -> 40 | P64: =G64*I64/$B$3/($B$2*9.81*0.5) -> 0.27498616
B65: 55 | C65: 60110094 | D65: 290 | E65: 10.5 | F65: 177 | G65: 40 | H65: =$B$2/2*9.81*$B$3/G65 -> 120.78563 | I65: =F65-H65 -> 56.214375 | J65: =I65-$M$4 -> -5.985625 | K65: =IF(J65<=0,"KO","OK") -> KO | L65: =D65-H65 -> 169.21437 | M65: =D65-L65 -> 120.78563 | O65: =G65/$B$3^2 -> 40 | P65: =G65*I65/$B$3/($B$2*9.81*0.5) -> 0.46540617
B66: 56 | C66: 60110072 | D66: 250 | E66: 10.5 | F66: 145 | G66: 45 | H66: =$B$2/2*9.81*$B$3/G66 -> 107.365 | I66: =F66-H66 -> 37.635 | J66: =I66-$M$4 -> -24.565 | K66: =IF(J66<=0,"KO","OK") -> KO | L66: =D66-H66 -> 142.635 | M66: =D66-L66 -> 107.365 | O66: =G66/$B$3^2 -> 45 | P66: =G66*I66/$B$3/($B$2*9.81*0.5) -> 0.35053323
... B156: 146 | C156: 60110089 | D156: 100 | E156: 14 | F156: 37 | G156: 340 | H156: =$B$2/2*9.81*$B$3/G156 -> 14.210074 | I156: =F156-H156 -> 22.789926 | J156: =I156-$M$4 -> -39.410074 | K156: =IF(J156<=0,"KO","OK") -> KO | L156: =D156-H156 -> 85.789926 | M156: =D156-L156 -> 14.210074 | O156: =G156/$B$3^2 -> 340 | P156: =G156*I156/$B$3/($B$2*9.81*0.5) -> 1.6037867
A157: Inner diameter 71mm | B157: 147 | C157: 60110125 | D157: 250 | E157: 12 | F157: 148 | G157: 60 | H157: =$B$2/2*9.81*$B$3/G157 -> 80.52375 | I157: =F157-H157 -> 67.47625 | J157: =I157-$M$4 -> 5.27625 | K157: =IF(J157<=0,"KO","OK") -> OK | L157: =D157-H157 -> 169.47625 | M157: =D157-L157 -> 80.52375 | O157: =G157/$B$3^2 -> 60 | P157: =G157*I157/$B$3/($B$2*9.81*0.5) -> 0.83796706
B158: 148 | C158: 60110124 | D158: 200 | E158: 11.75 | F158: 117 | G158: 70 | H158: =$B$2/2*9.81*$B$3/G158 -> 69.020357 | I158: =F158-H158 -> 47.979643 | J158: =I158-$M$4 -> -14.220357 | K158: =IF(J158<=0,"KO","OK") -> KO | L158: =D158-H158 -> 130.97964 | M158: =D158-L158 -> 69.020357 | O158: =G158/$B$3^2 -> 70 | P158: =G158*I158/$B$3/($B$2*9.81*0.5) -> 0.69515205
B159: 149 | C159: 60110126 | D159: 250 | E159: 12.5 | F159: 145 | G159: 70 | H159: =$B$2/2*9.81*$B$3/G159 -> 69.020357 | I159: =F159-H159 -> 75.979643 | J159: =I159-$M$4 -> 13.779643 | K159: =IF(J159<=0,"KO","OK") -> OK | L159: =D159-H159 -> 180.97964 | M159: =D159-L159 -> 69.020357 | O159: =G159/$B$3^2 -> 70 | P159: =G159*I159/$B$3/($B$2*9.81*0.5) -> 1.1008295
B160: 150 | C160: 60110146 | D160: 170 | E160: 11.9 | F160: 100 | G160: 80 | H160: =$B$2/2*9.81*$B$3/G160 -> 60.392813 | I160: =F160-H160 -> 39.607187 | J160: =I160-$M$4 -> -22.592812 | K160: =IF(J160<=0,"KO","OK") -> KO | L160: =D160-H160 -> 109.60719 | M160: =D160-L160 -> 60.392813 | O160: =G160/$B$3^2 -> 80 | P160: =G160*I160/$B$3/($B$2*9.81*0.5) -> 0.65582618
...

Sheet rear damper
B2: Strut housing length C [mm] | C2: Stroke B [mm] | E2: NO HLS | M2: Color code | O2: Helper springs
B3: 150 | C3: 75 | E3: L_actuator | F3: 0 | G3: [mm] | M3: Formula result | O3: Inner diameter 51 mm
B4: 175 | C4: 100 | E4: Stroke | F4: 0 | G4: [mm] | M4: Input data | O4: Spring rate [N/mm] | P4: Free length [mm] | Q4: Max spring travel [mm] | R4: Part - No.
B5: 200 | C5: 125 | M5: Constrained input data | O5: 5 | P5: 80 | Q5: 55 | R5: 60110144
B6: 225 | C6: 150 | E6: NO HLS | M6: Result = OK | O6: 20 | P6: 60 | Q6: 46 | R6: 60110028
B7: 250 | C7: 175 | E7: L_actuator | F7: 0 | G7: [mm] | M7: Result = KO | O7: Inner diameter 61 mm
B8: 270 | C8: 195 | E8: Stroke | F8: 0 | G8: [mm] | O8: 3 | P8: 80 | Q8: 68 | R8: 60110100
B9: 300 | C9: 225 | O9: 10 | P9: 80 | Q9: 55 | R9: 60110028
O10: 20 | P10: 80 | Q10: 45 | R10: 60110005
B11: Other dimensions [mm] | F11: Spring travel | O11: 40 | P11: 60 | Q11: 44 | R11: 60110080
B12: A | C12: 77.5 | E12: 1 | F12: Travel | G12: Bump | H12: Rebound | O12: 50 | P12: 60 | Q12: 43 | R12: 60110081
B13: D | C13: 23 | E13: =VLOOKUP($E$12,'rear wheel travel'!$A$13:$E$15,2) -> Race | F13: =H13+G13 -> 119.9 | G13: ='rear spring'!M4 -> 62.2 | H13: ='rear spring'!J8-'rear spring'!G8 -> 57.7 | O13: 60 | P13: 60 | Q13: 36 | R13: 60110092
B14: E | C14: 35.5 | O14: Inner diameter 71 mm
B15: F | C15: 13 | O15: 15 | P15: 80 | Q15: 53 | R15: 60110122
B16: G | C16: 3
B17: H | C17: 11.5
E21: REBOUND TRAVEL [mm] | F21: Coilover desired static length [mm] | G21: BUMP TRAVEL [mm] | I21: INBOARD | M21: STOPS LENGTH | P21: correction
C22: D | D22: =$C$13 -> 23 | E22: =SUM(D22:D25)-F23 -> 74.7 | I22: Coilover pack | M22: Bump | N22: =G24-G13 -> 13.1 | O22: [mm]
C23: C | D23: 225 | F23: ='rear spring'!G8 -> 400.8 | I23: H | J23: =$C$17 -> 11.5 | K23: [mm] | M23: Rebound | N23: =E22-H13 -> 17 | O23: [mm]
C24: B | D24: =VLOOKUP($D$23,$B$3:$C$9,2) -> 150 | G24: =D24-E22 -> 75.3 | I24: Spring static length | J24: =$G$30 -> 132.83519 | K24: [mm]
C25: A | D25: =$C$12 -> 77.5 | I25: G | J25: =$C$16 -> 3 | K25: [mm] | M25: FULL REBOUND SPRING CHECK
E26: =IF(E22>=H13,"OK","KO") -> OK | G26: =IF(G24>=G13,"OK","KO") -> OK | I26: Helper static legth | J26: =$P$9-$Q$9 -> 25 | K26: [mm] | M26: Coilover pack length in max rebound - allowed by strut | N26: =J30+E22 -> 260.03519 | O26: [mm]
I27: L_actuator | J27: =$F$3 -> 0 | K27: [mm] | M27: Coilover pack free length | N27: =D30+J28+P9+J27+J25+J23 -> 277.5 | O27: [mm]
A28: SELECTED SPRINGS | I28: F | J28: =$C$15 -> 13 | K28: [mm] | M28: Coilover pack length in max rebound - considering rebound stop | N28: =N26-N23 -> 243.03519 | O28: [mm]
A29: Index | B29: Part-No. | C29: Spring rate [N/mm] | D29: Free length [mm] | E29: Max spring travel Sn [mm] | F29: Spring static travel [mm] | G29: Static spring length | M29: Spring compression needed when assembling | N29: =N27-(J31+H13) -> -45 | O29: [mm]
A30: 112 | B30: =VLOOKUP($A30,'rear spring'!$B$11:$M$166,2) -> 60110115 | C30: =VLOOKUP($A30,'rear spring'!$B$11:$M$166,6) -> 130 | D30: =VLOOKUP($A30,'rear spring'!$B$11:$M$166,3) -> 170 | E30: =VLOOKUP($A30,'rear spring'!$B$11:$M$166,5) -> 88 | F30: =VLOOKUP($A30,'rear spring'!$B$11:$M$166,7) -> 37.164808 | G30: =VLOOKUP($A30,'rear spring'!$B$11:$M$166,11) -> 132.83519 | I30: Coilover static pack length | J30: =SUM(J23:J28) -> 185.33519 | K30: [mm] | N30: Rebound | P30: Bump | Q30: tot
A31: 116 | B31: =VLOOKUP($A31,'rear spring'!$B$11:$M$166,2) -> 60110145 | C31: =VLOOKUP($A31,'rear spring'!$B$11:$M$166,6) -> 140 | D31: =VLOOKUP($A31,'rear spring'!$B$11:$M$166,3) -> 200 | E31: =VLOOKUP($A31,'rear spring'!$B$11:$M$166,5) -> 92 | F31: =VLOOKUP($A31,'rear spring'!$B$11:$M$166,7) -> 34.510179 | G31: =VLOOKUP($A31,'rear spring'!$B$11:$M$166,11) -> 165.48982 | I31: Max static pack length allowed | J31: =$F$23-$C$12-$C$13-$C$14 -> 264.8 | K31: [mm] | M31: Corsa dell'ammortizzatore | N31: =E22 -> 74.7 | P31: =G24 -> 75.3 | Q31: =P31+N31 -> 150
A32: 118 | B32: =VLOOKUP($A32,'rear spring'!$B$11:$M$166,2) -> 60110116 | C32: =VLOOKUP($A32,'rear spring'!$B$11:$M$166,6) -> 150 | D32: =VLOOKUP($A32,'rear spring'!$B$11:$M$166,3) -> 170 | E32: =VLOOKUP($A32,'rear spring'!$B$11:$M$166,5) -> 85 | F32: =VLOOKUP($A32,'rear spring'!$B$11:$M$166,7) -> 32.2095 | G32: =VLOOKUP($A32,'rear spring'!$B$11:$M$166,11) -> 137.7905 | I32: Preload decrease adjustment [R] | J32: =J31-J30 -> 79.464808 | K32: [mm] | M32: Corsa della molla | N32: =F30 -> 37.164808 | P32: =E30-F30 -> 50.835192 | Q32: =P32+N32 -> 88
A33: 123 | B33: =VLOOKUP($A33,'rear spring'!$B$11:$M$166,2) -> 60110114 | C33: =VLOOKUP($A33,'rear spring'!$B$11:$M$166,6) -> 170 | D33: =VLOOKUP($A33,'rear spring'!$B$11:$M$166,3) -> 170 | E33: =VLOOKUP($A33,'rear spring'!$B$11:$M$166,5) -> 82 | F33: =VLOOKUP($A33,'rear spring'!$B$11:$M$166,7) -> 28.420147 | G33: =VLOOKUP($A33,'rear spring'!$B$11:$M$166,11) -> 141.57985 | I33: Preload decrease adjustment | J33: =C30*J32 -> 10330.425 | K33: [N] | M33: Scuotimento della ruota in funzione dello scuotimento della molla | N33: =N32*N35 -> 37.164808 | O33: =IF(N33<=45,"KO","OK") -> KO | P33: =P32*N35 -> 50.835192 | Q33: =IF(P33<=55,"KO","OK") -> KO
A34: 128 | B34: =VLOOKUP($A34,'rear spring'!$B$11:$M$166,2) -> 60110117 | C34: =VLOOKUP($A34,'rear spring'!$B$11:$M$166,6) -> 190 | D34: =VLOOKUP($A34,'rear spring'!$B$11:$M$166,3) -> 170 | E34: =VLOOKUP($A34,'rear spring'!$B$11:$M$166,5) -> 78 | F34: =VLOOKUP($A34,'rear spring'!$B$11:$M$166,7) -> 25.428553 | G34: =VLOOKUP($A34,'rear spring'!$B$11:$M$166,11) -> 144.57145 | I34: Preload increase adjustment | J34: =D23-C14-J32-C15-F3-F4 -> 97.035192 | K34: [mm] | M34: Scuotimento della ruota in funzione dello scuotimento dell'ammortizzatore | N34: =N35*N31 -> 74.7 | P34: =N35*P31 -> 75.3
I35: Preload increase adjustment | J35: =C30*J34 -> 12614.575 | K35: [N] | M35: Motion ratio | N35: ='rear motion ratio'!C15 -> 1

Sheet Roll Stiffness
B2: SCG004C | F2: Input
B3: Mass | C3: 2250 | D3: [kg]
B4: Front balance | C4: 0.5 | D4: [%]
B5: CGH | C5: 500 | D5: [mm]
B6: Front RCH | C6: 140 | D6: [mm]
B7: Rear RCH | C7: 140 | D7: [mm]
B8: Front roll moment arm | C8: =$C$5-C6 -> 360 | D8: [mm]
B9: Rear roll moment arm | C9: =$C$5-C7 -> 360 | D9: [mm]
B10: Front moment | C10: =C3*C4*C8/1000*9.81 -> 3973.05 | D10: [Nm/g] | F10: =C10+C11 -> 7946.1
B11: Rear moment | C11: =C3*(1-C4)*C9/1000*9.81 -> 3973.05 | D11: [Nm/g]
B12: Front moment balance | C12: =C10/(C10+C11) -> 0.5 | D12: [%]
B14: Front Track | C14: 1890 | D14: [mm]
B15: Rear Track | C15: 1890 | D15: [mm]
B16: Front spring stiffness | C16: 55 | D16: [N/mm]
B17: Rear spring stiffness | C17: 55 | D17: [N/mm]
B18: Front spring motion ratio | C18: ='front motion ratio'!C15 -> 1 | D18: [ratio]
B19: Rear spring motion ratio | C19: ='rear motion ratio'!C15 -> 1 | D19: [ratio]
B20: Front stiffness at ground (1-dof) | C20: =C16 -> 55 | D20: [N/mm]
B21: Rear stiffness at ground (1-dof) | C21: =C17 -> 55 | D21: [N/mm]
B22: Front delta jounce | C22: =TAN(1/57.325)*C14 -> 32.973253 | D22: [mm/deg]
B23: Rear delta jounce | C23: =TAN(1/57.325)*C15 -> 32.973253 | D23: [mm/deg] | F23: =C23/2 -> 16.486627
B24: Front delta force (ΔFz) | C24: =C22*C20 -> 1813.5289 | D24: [N/deg]
B25: Rear delta force (ΔFz) | C25: =C23*C21 -> 1813.5289 | D25: [N/deg]
B26: Front delta force balance | C26: =C24/(C24+C25) -> 0.5 | D26: [%]
B27: Front elastic roll stiffness | C27: =C24*C14/2/1000 -> 1713.7848 | D27: [Nm/deg]
B28: Rear elastic roll stiffness | C28: =C25*C15/2/1000 -> 1713.7848 | D28: [Nm/deg]
B29: Front roll stiffness balance | C29: =C27/(C27+C28) -> 0.5 | D29: [%]
B30: Total roll gradient (without AR) | C30: =(C10+C11)/(C27+C28) -> 2.3182899 | D30: deg/g
B32: Front ARB | C32: 500 | D32: [Nm/deg]
B33: Rear ARB | C33: 500 | D33: [Nm/deg]
B34: Front elastic roll stiffness (w ARB) | C34: =C27+C32 -> 2213.7848 | D34: [Nm/deg]
B35: Rear elastic roll stiffness (w ARB) | C35: =C28+C33 -> 2213.7848 | D35: [Nm/deg]
B36: Front roll stiffness balance (w ARB) | C36: =(C27+C32)/(C27+C32+C28+C33) -> 0.5 | D36: [%] | E36: Stock roll-bar 1200 N/mm
B37: Total roll gradient (without AR) | C37: =(C10+C11)/(C27+C28+C32+C33) -> 1.7946866 | D37: deg/g
B39: Milliken simplified front ΔFz vs ay | C39: =C3*9.81/C14*((C8*C27)/(C27+C28)+C4*C6) -> 2919.6429 | D39: [N/g]
B40: Milliken simplified rear ΔFz vs ay | C40: =C3*9.81/C15*((C9*C28)/(C27+C28)+(1-C4)*C7) -> 2919.6429 | D40: [N/g]
B41: Balance without ARBs | C41: =C39/(C39+C40) -> 0.5 | D41: [%]
B43: Milliken simplified front ΔFz vs ay | C43: =C3*9.81/C14*((C8*C34)/(C34+C35)+(C4)*C6) -> 2919.6429 | D43: [N/g]
B44: Milliken simplified rear ΔFz vs ay | C44: =C3*9.81/C15*((C9*C35)/(C34+C35)+(1-C4)*C7) -> 2919.6429 | D44: [N/g]
B45: Balance with ARBs | C45: =C43/(C43+C44) -> 0.5 | D45: [%]

Sheet Target Roll Stiffness
B2: m | C2: ='Roll Stiffness'!C3 -> 2250 | E2: Kf | F2: Kr | G2: χ front | H2: χ rear | I2: ΔFz front | J2: ΔFz rear | K2: Sum | L2: Front ΔFz ratio | M2: Front Fz ratio
B3: ay | C3: =9.81*1.5 -> 14.715 | E3: 0 | F3: =1-E3 -> 1 | G3: =$C$10-E3 -> 0.5 | H3: =$C$9-F3 -> -0.5 | I3: =$C$2*$C$3/$C$4*($C$6*E3-$C$7*G3) -> -1226.25 | J3: =$C$2*$C$3/$C$5*($C$6*F3+$C$8*H3) -> 7532.6786 | K3: =J3+I3 -> 6306.4286 | L3: =I3/K3 -> -0.19444444 | M3: =($C$11+I3)/($C$11+I3+$C$12+J3) -> 0.24747475
B4: Tf | C4: ='Roll Stiffness'!C14 -> 1890 | E4: =E3+0.05 -> 0.05 | F4: =1-E4 -> 0.95 | G4: =$C$10-E4 -> 0.45 | H4: =$C$9-F4 -> -0.45 | I4: =$C$2*$C$3/$C$4*($C$6*E4-$C$7*G4) -> -665.67857 | J4: =$C$2*$C$3/$C$5*($C$6*F4+$C$8*H4) -> 7217.3571 | K4: =J4+I4 -> 6551.6786 | L4: =I4/K4 -> -0.10160428 | M4: =($C$11+I4)/($C$11+I4+$C$12+J4) -> 0.27589641
B5: Tr | C5: ='Roll Stiffness'!C15 -> 1890 | E5: =E4+0.05 -> 0.1 | F5: =1-E5 -> 0.9 | G5: =$C$10-E5 -> 0.4 | H5: =$C$9-F5 -> -0.4 | I5: =$C$2*$C$3/$C$4*($C$6*E5-$C$7*G5) -> -105.10714 | J5: =$C$2*$C$3/$C$5*($C$6*F5+$C$8*H5) -> 6902.0357 | K5: =J5+I5 -> 6796.9286 | L5: =I5/K5 -> -0.015463918 | M5: =($C$11+I5)/($C$11+I5+$C$12+J5) -> 0.30353635
B6: hG | C6: ='Roll Stiffness'!C5 -> 500 | E6: =E5+0.05 -> 0.15 | F6: =1-E6 -> 0.85 | G6: =$C$10-E6 -> 0.35 | H6: =$C$9-F6 -> -0.35 | I6: =$C$2*$C$3/$C$4*($C$6*E6-$C$7*G6) -> 455.46429 | J6: =$C$2*$C$3/$C$5*($C$6*F6+$C$8*H6) -> 6586.7143 | K6: =J6+I6 -> 7042.1786 | L6: =I6/K6 -> 0.064676617 | M6: =($C$11+I6)/($C$11+I6+$C$12+J6) -> 0.33042636
B7: RCHf | C7: ='Roll Stiffness'!C6 -> 140 | E7: =E6+0.05 -> 0.2 | F7: =1-E7 -> 0.8 | G7: =$C$10-E7 -> 0.3 | H7: =$C$9-F7 -> -0.3 | I7: =$C$2*$C$3/$C$4*($C$6*E7-$C$7*G7) -> 1016.0357 | J7: =$C$2*$C$3/$C$5*($C$6*F7+$C$8*H7) -> 6271.3929 | K7: =J7+I7 -> 7287.4286 | L7: =I7/K7 -> 0.13942308 | M7: =($C$11+I7)/($C$11+I7+$C$12+J7) -> 0.35659656
B8: RCHr | C8: ='Roll Stiffness'!C7 -> 140 | E8: =E7+0.05 -> 0.25 | F8: =1-E8 -> 0.75 | G8: =$C$10-E8 -> 0.25 | H8: =$C$9-F8 -> -0.25 | I8: =$C$2*$C$3/$C$4*($C$6*E8-$C$7*G8) -> 1576.6071 | J8: =$C$2*$C$3/$C$5*($C$6*F8+$C$8*H8) -> 5956.0714 | K8: =J8+I8 -> 7532.6786 | L8: =I8/K8 -> 0.20930233 | M8: =($C$11+I8)/($C$11+I8+$C$12+J8) -> 0.38207547
B9: a/L | C9: =1-'Roll Stiffness'!C4 -> 0.5 | E9: =E8+0.05 -> 0.3 | F9: =1-E9 -> 0.7 | G9: =$C$10-E9 -> 0.2 | H9: =$C$9-F9 -> -0.2 | I9: =$C$2*$C$3/$C$4*($C$6*E9-$C$7*G9) -> 2137.1786 | J9: =$C$2*$C$3/$C$5*($C$6*F9+$C$8*H9) -> 5640.75 | K9: =J9+I9 -> 7777.9286 | L9: =I9/K9 -> 0.27477477 | M9: =($C$11+I9)/($C$11+I9+$C$12+J9) -> 0.40689013
B10: b/L | C10: ='Roll Stiffness'!C4 -> 0.5 | E10: =E9+0.05 -> 0.35 | F10: =1-E10 -> 0.65 | G10: =$C$10-E10 -> 0.15 | H10: =$C$9-F10 -> -0.15 | I10: =$C$2*$C$3/$C$4*($C$6*E10-$C$7*G10) -> 2697.75 | J10: =$C$2*$C$3/$C$5*($C$6*F10+$C$8*H10) -> 5325.4286 | K10: =J10+I10 -> 8023.1786 | L10: =I10/K10 -> 0.33624454 | M10: =($C$11+I10)/($C$11+I10+$C$12+J10) -> 0.43106618
B11: Fz front | C11: =C2*9.81*C10/2 -> 5518.125 | E11: 0.37 | F11: =1-E11 -> 0.63 | G11: =$C$10-E11 -> 0.13 | H11: =$C$9-F11 -> -0.13 | I11: =$C$2*$C$3/$C$4*($C$6*E11-$C$7*G11) -> 2921.9786 | J11: =$C$2*$C$3/$C$5*($C$6*F11+$C$8*H11) -> 5199.3 | K11: =J11+I11 -> 8121.2786 | L11: =I11/K11 -> 0.35979292 | M11: =($C$11+I11)/($C$11+I11+$C$12+J11) -> 0.44056328
B12: Fz rear | C12: =C2*9.81*C9/2 -> 5518.125 | E12: =E10+0.05 -> 0.4 | F12: =1-E12 -> 0.6 | G12: =$C$10-E12 -> 0.1 | H12: =$C$9-F12 -> -0.1 | I12: =$C$2*$C$3/$C$4*($C$6*E12-$C$7*G12) -> 3258.3214 | J12: =$C$2*$C$3/$C$5*($C$6*F12+$C$8*H12) -> 5010.1071 | K12: =J12+I12 -> 8268.4286 | L12: =I12/K12 -> 0.3940678 | M12: =($C$11+I12)/($C$11+I12+$C$12+J12) -> 0.45462795
E13: =E12+0.05 -> 0.45 | F13: =1-E13 -> 0.55 | G13: =$C$10-E13 -> 0.05 | H13: =$C$9-F13 -> -0.05 | I13: =$C$2*$C$3/$C$4*($C$6*E13-$C$7*G13) -> 3818.8929 | J13: =$C$2*$C$3/$C$5*($C$6*F13+$C$8*H13) -> 4694.7857 | K13: =J13+I13 -> 8513.6786 | L13: =I13/K13 -> 0.44855967 | M13: =($C$11+I13)/($C$11+I13+$C$12+J13) -> 0.47759857
E14: =E13+0.05 -> 0.5 | F14: =1-E14 -> 0.5 | G14: =$C$10-E14 -> 0 | H14: =$C$9-F14 -> 0 | I14: =$C$2*$C$3/$C$4*($C$6*E14-$C$7*G14) -> 4379.4643 | J14: =$C$2*$C$3/$C$5*($C$6*F14+$C$8*H14) -> 4379.4643 | K14: =J14+I14 -> 8758.9286 | L14: =I14/K14 -> 0.5 | M14: =($C$11+I14)/($C$11+I14+$C$12+J14) -> 0.5
E15: 0.51 | F15: =1-E15 -> 0.49 | G15: =$C$10-E15 -> -0.01 | H15: =$C$9-F15 -> 0.01 | I15: =$C$2*$C$3/$C$4*($C$6*E15-$C$7*G15) -> 4491.5786 | J15: =$C$2*$C$3/$C$5*($C$6*F15+$C$8*H15) -> 4316.4 | K15: =J15+I15 -> 8807.9786 | L15: =I15/K15 -> 0.50994431 | M15: =($C$11+I15)/($C$11+I15+$C$12+J15) -> 0.50441384
E16: =E14+0.05 -> 0.55 | F16: =1-E16 -> 0.45 | G16: =$C$10-E16 -> -0.05 | H16: =$C$9-F16 -> 0.05 | I16: =$C$2*$C$3/$C$4*($C$6*E16-$C$7*G16) -> 4940.0357 | J16: =$C$2*$C$3/$C$5*($C$6*F16+$C$8*H16) -> 4064.1429 | K16: =J16+I16 -> 9004.1786 | L16: =I16/K16 -> 0.54863813 | M16: =($C$11+I16)/($C$11+I16+$C$12+J16) -> 0.52185315
E17: =E16+0.05 -> 0.6 | F17: =1-E17 -> 0.4 | G17: =$C$10-E17 -> -0.1 | H17: =$C$9-F17 -> 0.1 | I17: =$C$2*$C$3/$C$4*($C$6*E17-$C$7*G17) -> 5500.6071 | J17: =$C$2*$C$3/$C$5*($C$6*F17+$C$8*H17) -> 3748.8214 | K17: =J17+I17 -> 9249.4286 | L17: =I17/K17 -> 0.59469697 | M17: =($C$11+I17)/($C$11+I17+$C$12+J17) -> 0.54317789
E18: =E17+0.05 -> 0.65 | F18: =1-E18 -> 0.35 | G18: =$C$10-E18 -> -0.15 | H18: =$C$9-F18 -> 0.15 | I18: =$C$2*$C$3/$C$4*($C$6*E18-$C$7*G18) -> 6061.1786 | J18: =$C$2*$C$3/$C$5*($C$6*F18+$C$8*H18) -> 3433.5 | K18: =J18+I18 -> 9494.6786 | L18: =I18/K18 -> 0.63837638 | M18: =($C$11+I18)/($C$11+I18+$C$12+J18) -> 0.56399317
E19: =E18+0.05 -> 0.7 | F19: =1-E19 -> 0.3 | G19: =$C$10-E19 -> -0.2 | H19: =$C$9-F19 -> 0.2 | I19: =$C$2*$C$3/$C$4*($C$6*E19-$C$7*G19) -> 6621.75 | J19: =$C$2*$C$3/$C$5*($C$6*F19+$C$8*H19) -> 3118.1786 | K19: =J19+I19 -> 9739.9286 | L19: =I19/K19 -> 0.67985612 | M19: =($C$11+I19)/($C$11+I19+$C$12+J19) -> 0.58431703
E20: =E19+0.05 -> 0.75 | F20: =1-E20 -> 0.25 | G20: =$C$10-E20 -> -0.25 | H20: =$C$9-F20 -> 0.25 | I20: =$C$2*$C$3/$C$4*($C$6*E20-$C$7*G20) -> 7182.3214 | J20: =$C$2*$C$3/$C$5*($C$6*F20+$C$8*H20) -> 2802.8571 | K20: =J20+I20 -> 9985.1786 | L20: =I20/K20 -> 0.71929825 | M20: =($C$11+I20)/($C$11+I20+$C$12+J20) -> 0.60416667
E21: 0.77 | F21: =1-E21 -> 0.23 | G21: =$C$10-E21 -> -0.27 | H21: =$C$9-F21 -> 0.27 | I21: =$C$2*$C$3/$C$4*($C$6*E21-$C$7*G21) -> 7406.55 | J21: =$C$2*$C$3/$C$5*($C$6*F21+$C$8*H21) -> 2676.7286 | K21: =J21+I21 -> 10083.279 | L21: =I21/K21 -> 0.73453787 | M21: =($C$11+I21)/($C$11+I21+$C$12+J21) -> 0.61197744
E22: =E20+0.05 -> 0.8 | F22: =1-E22 -> 0.2 | G22: =$C$10-E22 -> -0.3 | H22: =$C$9-F22 -> 0.3 | I22: =$C$2*$C$3/$C$4*($C$6*E22-$C$7*G22) -> 7742.8929 | J22: =$C$2*$C$3/$C$5*($C$6*F22+$C$8*H22) -> 2487.5357 | K22: =J22+I22 -> 10230.429 | L22: =I22/K22 -> 0.75684932 | M22: =($C$11+I22)/($C$11+I22+$C$12+J22) -> 0.62355848
E23: =E22+0.05 -> 0.85 | F23: =1-E23 -> 0.15 | G23: =$C$10-E23 -> -0.35 | H23: =$C$9-F23 -> 0.35 | I23: =$C$2*$C$3/$C$4*($C$6*E23-$C$7*G23) -> 8303.4643 | J23: =$C$2*$C$3/$C$5*($C$6*F23+$C$8*H23) -> 2172.2143 | K23: =J23+I23 -> 10475.679 | L23: =I23/K23 -> 0.79264214 | M23: =($C$11+I23)/($C$11+I23+$C$12+J23) -> 0.64250814
E24: =E23+0.05 -> 0.9 | F24: =1-E24 -> 0.1 | G24: =$C$10-E24 -> -0.4 | H24: =$C$9-F24 -> 0.4 | I24: =$C$2*$C$3/$C$4*($C$6*E24-$C$7*G24) -> 8864.0357 | J24: =$C$2*$C$3/$C$5*($C$6*F24+$C$8*H24) -> 1856.8929 | K24: =J24+I24 -> 10720.929 | L24: =I24/K24 -> 0.82679739 | M24: =($C$11+I24)/($C$11+I24+$C$12+J24) -> 0.6610306
E25: =E24+0.05 -> 0.95 | F25: =1-E25 -> 0.05 | G25: =$C$10-E25 -> -0.45 | H25: =$C$9-F25 -> 0.45 | I25: =$C$2*$C$3/$C$4*($C$6*E25-$C$7*G25) -> 9424.6071 | J25: =$C$2*$C$3/$C$5*($C$6*F25+$C$8*H25) -> 1541.5714 | K25: =J25+I25 -> 10966.179 | L25: =I25/K25 -> 0.85942492 | M25: =($C$11+I25)/($C$11+I25+$C$12+J25) -> 0.67914013
E26: =E25+0.05 -> 1 | F26: =1-E26 -> 0 | G26: =$C$10-E26 -> -0.5 | H26: =$C$9-F26 -> 0.5 | I26: =$C$2*$C$3/$C$4*($C$6*E26-$C$7*G26) -> 9985.1786 | J26: =$C$2*$C$3/$C$5*($C$6*F26+$C$8*H26) -> 1226.25 | K26: =J26+I26 -> 11211.429 | L26: =I26/K26 -> 0.890625 | M26: =($C$11+I26)/($C$11+I26+$C$12+J26) -> 0.69685039

Sheet spring
A3: Parameters | C3: Unit | D3: Note | F3: Color code
A4: D | B4: =51+B5 -> 63 | C4: [mm] | F4: Formula result | H4: Calcolo online
A5: d | B5: 12 | C5: [mm] | D5: =+IF(B5>=B14,"d must be smaller than pitch","ok") -> ok | F5: Input data
A6: c | B6: =B4/B5 -> 5.25 | C6: [] | D6: Characteristic ratio (7 or 12) | F6: Constrained input data
A7: F | B7: =120*48 -> 5760 | C7: [N] | F7: Result = OK
A8: λ' | B8: 1.7 | C8: [] | D8: From graph | F8: Result = KO
A9: λ'' | B9: 0.98 | C9: [] | D9: From graph
A10: λ' | B10: =IF(AND(B6 >=7,B6<=12),(4*B6-1)/(4*B6-4)+0.615/B6,B8) -> 1.7 | C10: []
A11: λ'' | B11: =IF(AND(B6 >=7,B6<=12),1,B9) -> 0.98 | C11: []
A12: Type of end | B12: 2 | C12: []
A13: i | B13: 5 | C13: [] | D13: Number of active coils
A14: p | B14: 25 | C14: [mm] | D14: Pitch
A15: n | B15: =CHOOSE(B12,B13,B13,B13+2,B13+2) -> 5 | D15: Number of coils
A16: L_0 | B16: =CHOOSE(B12,B13*B14+B5,B13*B14,B13*B14+3*B5,B13*B14+2*B5) -> 125 | C16: [mm] | D16: Free length
A17: L_b | B17: =CHOOSE(B12,(B13+1)*B5,B13*B5,(B13+3)*B5,(B13+2)*B5) -> 60 | C17: [mm] | D17: Minimum Length
A18: g_res | B18: 0 | C18: [mm] | D18: Residual play among coils (adv. d/4)
A19: L_min | B19: =B17+B18*B13 -> 60 | C19: [mm]
A20: Travel | B20: =B16-B19 -> 65 | C20: [mm]
A21: τ_max | B21: =B10*B7*0.5*B4/(PI()*B5^3/16) -> 909.09303 | C21: [MPa]
A22: E | B22: 206000 | C22: [MPa] | D22: Young Modulus
A23: ν | B23: 0.3 | D23: Poisson ratio
A24: f | B24: =B11*B7*(0.5*B4)^2*(PI()*B4*B13)/(PI()*B5^4*(B22/(2*(1+B23)))/32) -> 34.364604 | C24: [mm]
A25: k | B25: =B7/B24 -> 167.61433 | C25: [N/mm] | D25: Stiffness

Sheet P45 wheel travel
C2: Wheel travel while driving [mm]
